Workbook

Sheet Balance
A1: ESTADO DE SITUACION FINANCIERA | G1: 2021 | H1: 2022 | I1: 2023 | J1: 2024 | K1: 2025 | AE1: ANÁLISIS VERTICAL (% del Activo Total) | AK1: ANÁLISIS HORIZONTAL - Variación absoluta | AP1: ANÁLISIS HORIZONTAL - Variación %
G2: 46295 | H2: 46295 | I2: 46295 | J2: 46295 | K2: 46295 | AE2: 2021 | AF2: 2022 | AG2: 2023 | AH2: 2024 | AI2: 2025 | AK2: 2022/2021 | AL2: 2023/2022 | AM2: 2024/2023 | AN2: 2025/2024 | AP2: 2022/2021 | AQ2: 2023/2022 | AR2: 2024/2023 | AS2: 2025/2024
A3: Total del activo corriente | G3: =SUM(G4,G6,G7,G10,G11,G12,G14) -> 27607 | H3: =SUM(H4,H6,H7,H10,H11,H12,H14) -> 30205 | I3: =SUM(I4,I6,I7,I10,I11,I12,I14) -> 33532 | J3: =SUM(J4,J6,J7,J10,J11,J12,J14) -> 34033 | K3: =SUM(K4,K6,K7,K10,K11,K12,K14) -> 37766 | AE3: =IFERROR(G3/G$17,0) -> 0.33303175 | AF3: =IFERROR(H3/H$17,0) -> 0.35327072 | AG3: =IFERROR(I3/I$17,0) -> 0.37052343 | AH3: =IFERROR(J3/J$17,0) -> 0.36009565 | AI3: =IFERROR(K3/K$17,0) -> 0.37907395 | AK3: =IFERROR(H3-G3,0) -> 2598 | AL3: =IFERROR(I3-H3,0) -> 3327 | AM3: =IFERROR(J3-I3,0) -> 501 | AN3: =IFERROR(K3-J3,0) -> 3733 | AP3: =IFERROR((H3-G3)/G3,0) -> 0.094106567 | AQ3: =IFERROR((I3-H3)/H3,0) -> 0.11014733 | AR3: =IFERROR((J3-I3)/I3,0) -> 0.014940952 | AS3: =IFERROR((K3-J3)/J3,0) -> 0.10968766
A4: Efectivo y equivalentes | G4: 16487 | H4: 15689 | I4: 16286 | J4: 11975 | K4: 17164 | AE4: =IFERROR(G4/G$17,0) -> 0.19888776 | AF4: =IFERROR(H4/H$17,0) -> 0.18349493 | AG4: =IFERROR(I4/I$17,0) -> 0.17995779 | AH4: =IFERROR(J4/J$17,0) -> 0.12670483 | AI4: =IFERROR(K4/K$17,0) -> 0.17228261 | AK4: =IFERROR(H4-G4,0) -> -798 | AL4: =IFERROR(I4-H4,0) -> 597 | AM4: =IFERROR(J4-I4,0) -> -4311 | AN4: =IFERROR(K4-J4,0) -> 5189 | AP4: =IFERROR((H4-G4)/G4,0) -> -0.048401771 | AQ4: =IFERROR((I4-H4)/H4,0) -> 0.038052138 | AR4: =IFERROR((J4-I4)/I4,0) -> -0.26470588 | AS4: =IFERROR((K4-J4)/J4,0) -> 0.43331942
A5: Crecimiento de efectivo y equivalentes | G5: 0.0122 | H5: =IFERROR((H4-G4)/G4,0) -> -0.048401771 | I5: =IFERROR((I4-H4)/H4,0) -> 0.038052138 | J5: =IFERROR((J4-I4)/I4,0) -> -0.26470588 | K5: =IFERROR((K4-J4)/J4,0) -> 0.43331942 | AE5: =IFERROR(G5/G$17,0) -> 1.4717236e-07 | AF5: =IFERROR(H5/H$17,0) -> -5.6609596e-07 | AG5: =IFERROR(I5/I$17,0) -> 4.2047026e-07 | AH5: =IFERROR(J5/J$17,0) -> -2.8007944e-06 | AI5: =IFERROR(K5/K$17,0) -> 4.3494175e-06 | AK5: =IFERROR(H5-G5,0) -> -0.060601771 | AL5: =IFERROR(I5-H5,0) -> 0.08645391 | AM5: =IFERROR(J5-I5,0) -> -0.30275802 | AN5: =IFERROR(K5-J5,0) -> 0.6980253 | AP5: =IFERROR((H5-G5)/G5,0) -> -4.9673583 | AQ5: =IFERROR((I5-H5)/H5,0) -> -1.7861724 | AR5: =IFERROR((J5-I5)/I5,0) -> -7.9563996 | AS5: =IFERROR((K5-J5)/J5,0) -> -2.6369845
A6: Inversiones a corto plazo | G6: 2025 | H6: 2833 | I6: 3842 | J6: 3200 | K6: 1833 | AE6: =IFERROR(G6/G$17,0) -> 0.024428199 | AF6: =IFERROR(H6/H$17,0) -> 0.033134115 | AG6: =IFERROR(I6/I$17,0) -> 0.042453508 | AH6: =IFERROR(J6/J$17,0) -> 0.033858493 | AI6: =IFERROR(K6/K$17,0) -> 0.018398627 | AK6: =IFERROR(H6-G6,0) -> 808 | AL6: =IFERROR(I6-H6,0) -> 1009 | AM6: =IFERROR(J6-I6,0) -> -642 | AN6: =IFERROR(K6-J6,0) -> -1367 | AP6: =IFERROR((H6-G6)/G6,0) -> 0.39901235 | AQ6: =IFERROR((I6-H6)/H6,0) -> 0.35615955 | AR6: =IFERROR((J6-I6)/I6,0) -> -0.16710047 | AS6: =IFERROR((K6-J6)/J6,0) -> -0.4271875
A7: Créditos totales | G7: =SUM(G8,G9) -> 3809 | H7: =SUM(H8,H9) -> 4142 | I7: =SUM(I8,I9) -> 4680 | J7: =SUM(J8,J9) -> 7847 | K7: =SUM(K8,K9) -> 7549 | AE7: =IFERROR(G7/G$17,0) -> 0.045949141 | AF7: =IFERROR(H7/H$17,0) -> 0.048443878 | AG7: =IFERROR(I7/I$17,0) -> 0.051713279 | AH7: =IFERROR(J7/J$17,0) -> 0.083027372 | AI7: =IFERROR(K7/K$17,0) -> 0.075772632 | AK7: =IFERROR(H7-G7,0) -> 333 | AL7: =IFERROR(I7-H7,0) -> 538 | AM7: =IFERROR(J7-I7,0) -> 3167 | AN7: =IFERROR(K7-J7,0) -> -298 | AP7: =IFERROR((H7-G7)/G7,0) -> 0.087424521 | AQ7: =IFERROR((I7-H7)/H7,0) -> 0.12988894 | AR7: =IFERROR((J7-I7)/I7,0) -> 0.6767094 | AS7: =IFERROR((K7-J7)/J7,0) -> -0.037976297
A8: Total de cuentas por cobrar | G8: 3726 | H8: 3952 | I8: 4474 | J8: 7015 | K8: 7317 | AE8: =IFERROR(G8/G$17,0) -> 0.044947887 | AF8: =IFERROR(H8/H$17,0) -> 0.046221682 | AG8: =IFERROR(I8/I$17,0) -> 0.04943701 | AH8: =IFERROR(J8/J$17,0) -> 0.074224164 | AI8: =IFERROR(K8/K$17,0) -> 0.073443946 | AK8: =IFERROR(H8-G8,0) -> 226 | AL8: =IFERROR(I8-H8,0) -> 522 | AM8: =IFERROR(J8-I8,0) -> 2541 | AN8: =IFERROR(K8-J8,0) -> 302 | AP8: =IFERROR((H8-G8)/G8,0) -> 0.060654858 | AQ8: =IFERROR((I8-H8)/H8,0) -> 0.13208502 | AR8: =IFERROR((J8-I8)/I8,0) -> 0.56794814 | AS8: =IFERROR((K8-J8)/J8,0) -> 0.043050606
A9: Otros créditos | G9: 83 | H9: 190 | I9: 206 | J9: 832 | K9: 232 | AE9: =IFERROR(G9/G$17,0) -> 0.0010012546 | AF9: =IFERROR(H9/H$17,0) -> 0.0022221962 | AG9: =IFERROR(I9/I$17,0) -> 0.0022762682 | AH9: =IFERROR(J9/J$17,0) -> 0.0088032081 | AI9: =IFERROR(K9/K$17,0) -> 0.002328686 | AK9: =IFERROR(H9-G9,0) -> 107 | AL9: =IFERROR(I9-H9,0) -> 16 | AM9: =IFERROR(J9-I9,0) -> 626 | AN9: =IFERROR(K9-J9,0) -> -600 | AP9: =IFERROR((H9-G9)/G9,0) -> 1.2891566 | AQ9: =IFERROR((I9-H9)/H9,0) -> 0.084210526 | AR9: =IFERROR((J9-I9)/I9,0) -> 3.038835 | AS9: =IFERROR((K9-J9)/J9,0) -> -0.72115385
A10: Inventario | G10: - | H10: - | I10: - | J10: - | K10: - | AE10: =IFERROR(G10/G$17,0) -> 0 | AF10: =IFERROR(H10/H$17,0) -> 0 | AG10: =IFERROR(I10/I$17,0) -> 0 | AH10: =IFERROR(J10/J$17,0) -> 0 | AI10: =IFERROR(K10/K$17,0) -> 0 | AK10: =IFERROR(H10-G10,0) -> 0 | AL10: =IFERROR(I10-H10,0) -> 0 | AM10: =IFERROR(J10-I10,0) -> 0 | AN10: =IFERROR(K10-J10,0) -> 0 | AP10: =IFERROR((H10-G10)/G10,0) -> 0 | AQ10: =IFERROR((I10-H10)/H10,0) -> 0 | AR10: =IFERROR((J10-I10)/I10,0) -> 0 | AS10: =IFERROR((K10-J10)/J10,0) -> 0
A11: Gastos pagados por adelantado | G11: 613 | H11: 828 | I11: 1328 | J11: 1238 | K11: 985 | AE11: =IFERROR(G11/G$17,0) -> 0.007394808 | AF11: =IFERROR(H11/H$17,0) -> 0.0096840973 | AG11: =IFERROR(I11/I$17,0) -> 0.014674195 | AH11: =IFERROR(J11/J$17,0) -> 0.013099004 | AI11: =IFERROR(K11/K$17,0) -> 0.0098868781 | AK11: =IFERROR(H11-G11,0) -> 215 | AL11: =IFERROR(I11-H11,0) -> 500 | AM11: =IFERROR(J11-I11,0) -> -90 | AN11: =IFERROR(K11-J11,0) -> -253 | AP11: =IFERROR((H11-G11)/G11,0) -> 0.35073409 | AQ11: =IFERROR((I11-H11)/H11,0) -> 0.60386473 | AR11: =IFERROR((J11-I11)/I11,0) -> -0.067771084 | AS11: =IFERROR((K11-J11)/J11,0) -> -0.20436187
A12: División financiera, préstamos y arrendamientos corrientes | G12: - | H12: - | I12: - | J12: - | K12: - | AE12: =IFERROR(G12/G$17,0) -> 0 | AF12: =IFERROR(H12/H$17,0) -> 0 | AG12: =IFERROR(I12/I$17,0) -> 0 | AH12: =IFERROR(J12/J$17,0) -> 0 | AI12: =IFERROR(K12/K$17,0) -> 0 | AK12: =IFERROR(H12-G12,0) -> 0 | AL12: =IFERROR(I12-H12,0) -> 0 | AM12: =IFERROR(J12-I12,0) -> 0 | AN12: =IFERROR(K12-J12,0) -> 0 | AP12: =IFERROR((H12-G12)/G12,0) -> 0 | AQ12: =IFERROR((I12-H12)/H12,0) -> 0 | AR12: =IFERROR((J12-I12)/I12,0) -> 0 | AS12: =IFERROR((K12-J12)/J12,0) -> 0
A13: División financiera, total de otros activos corrientes | G13: - | H13: - | I13: - | J13: - | K13: - | AE13: =IFERROR(G13/G$17,0) -> 0 | AF13: =IFERROR(H13/H$17,0) -> 0 | AG13: =IFERROR(I13/I$17,0) -> 0 | AH13: =IFERROR(J13/J$17,0) -> 0 | AI13: =IFERROR(K13/K$17,0) -> 0 | AK13: =IFERROR(H13-G13,0) -> 0 | AL13: =IFERROR(I13-H13,0) -> 0 | AM13: =IFERROR(J13-I13,0) -> 0 | AN13: =IFERROR(K13-J13,0) -> 0 | AP13: =IFERROR((H13-G13)/G13,0) -> 0 | AQ13: =IFERROR((I13-H13)/H13,0) -> 0 | AR13: =IFERROR((J13-I13)/I13,0) -> 0 | AS13: =IFERROR((K13-J13)/J13,0) -> 0
A14: Otros activos corrientes | G14: =SUM(G15,G16) -> 4673 | H14: =SUM(H15,H16) -> 6713 | I14: =SUM(I15,I16) -> 7396 | J14: =SUM(J15,J16) -> 9773 | K14: =SUM(K15,K16) -> 10235 | AE14: =IFERROR(G14/G$17,0) -> 0.056371839 | AF14: =IFERROR(H14/H$17,0) -> 0.078513702 | AG14: =IFERROR(I14/I$17,0) -> 0.08172466 | AH14: =IFERROR(J14/J$17,0) -> 0.10340595 | AI14: =IFERROR(K14/K$17,0) -> 0.10273319 | AK14: =IFERROR(H14-G14,0) -> 2040 | AL14: =IFERROR(I14-H14,0) -> 683 | AM14: =IFERROR(J14-I14,0) -> 2377 | AN14: =IFERROR(K14-J14,0) -> 462 | AP14: =IFERROR((H14-G14)/G14,0) -> 0.4365504 | AQ14: =IFERROR((I14-H14)/H14,0) -> 0.10174289 | AR14: =IFERROR((J14-I14)/I14,0) -> 0.32138994 | AS14: =IFERROR((K14-J14)/J14,0) -> 0.047273099
A15: Efectivo restringido | G15: 1052 | H15: 2346 | I15: 2699 | J15: 4264 | K15: 4198 | AE15: =IFERROR(G15/G$17,0) -> 0.0126906 | AF15: =IFERROR(H15/H$17,0) -> 0.027438276 | AG15: =IFERROR(I15/I$17,0) -> 0.029823534 | AH15: =IFERROR(J15/J$17,0) -> 0.045116441 | AI15: =IFERROR(K15/K$17,0) -> 0.042137172 | AK15: =IFERROR(H15-G15,0) -> 1294 | AL15: =IFERROR(I15-H15,0) -> 353 | AM15: =IFERROR(J15-I15,0) -> 1565 | AN15: =IFERROR(K15-J15,0) -> -66 | AP15: =IFERROR((H15-G15)/G15,0) -> 1.230038 | AQ15: =IFERROR((I15-H15)/H15,0) -> 0.15046888 | AR15: =IFERROR((J15-I15)/I15,0) -> 0.57984439 | AS15: =IFERROR((K15-J15)/J15,0) -> -0.015478424
A16: Total de otros activos corrientes | G16: 3621 | H16: 4367 | I16: 4697 | J16: 5509 | K16: 6037 | AE16: =IFERROR(G16/G$17,0) -> 0.043681239 | AF16: =IFERROR(H16/H$17,0) -> 0.051075426 | AG16: =IFERROR(I16/I$17,0) -> 0.051901126 | AH16: =IFERROR(J16/J$17,0) -> 0.058289511 | AI16: =IFERROR(K16/K$17,0) -> 0.060596023 | AK16: =IFERROR(H16-G16,0) -> 746 | AL16: =IFERROR(I16-H16,0) -> 330 | AM16: =IFERROR(J16-I16,0) -> 812 | AN16: =IFERROR(K16-J16,0) -> 528 | AP16: =IFERROR((H16-G16)/G16,0) -> 0.20602044 | AQ16: =IFERROR((I16-H16)/H16,0) -> 0.075566751 | AR16: =IFERROR((J16-I16)/I16,0) -> 0.1728763 | AS16: =IFERROR((K16-J16)/J16,0) -> 0.095843166
A17: Activos totales | G17: =SUM(G3,G19,G22,G23,G27) -> 82896 | H17: =SUM(H3,H19,H22,H23,H27) -> 85501 | I17: =SUM(I3,I19,I22,I23,I27) -> 90499 | J17: =SUM(J3,J19,J22,J23,J27) -> 94511 | K17: =SUM(K3,K19,K22,K23,K27) -> 99627 | AE17: =IFERROR(G17/G$17,0) -> 1 | AF17: =IFERROR(H17/H$17,0) -> 1 | AG17: =IFERROR(I17/I$17,0) -> 1 | AH17: =IFERROR(J17/J$17,0) -> 1 | AI17: =IFERROR(K17/K$17,0) -> 1 | AK17: =IFERROR(H17-G17,0) -> 2605 | AL17: =IFERROR(I17-H17,0) -> 4998 | AM17: =IFERROR(J17-I17,0) -> 4012 | AN17: =IFERROR(K17-J17,0) -> 5116 | AP17: =IFERROR((H17-G17)/G17,0) -> 0.031424918 | AQ17: =IFERROR((I17-H17)/H17,0) -> 0.058455457 | AR17: =IFERROR((J17-I17)/I17,0) -> 0.044331982 | AS17: =IFERROR((K17-J17)/J17,0) -> 0.054131265
A18: Crecimiento de activos totales | G18: 0.0244 | H18: =IFERROR((H17-G17)/G17,0) -> 0.031424918 | I18: =IFERROR((I17-H17)/H17,0) -> 0.058455457 | J18: =IFERROR((J17-I17)/I17,0) -> 0.044331982 | K18: =IFERROR((K17-J17)/J17,0) -> 0.054131265 | AE18: =IFERROR(G18/G$17,0) -> 2.9434472e-07 | AF18: =IFERROR(H18/H$17,0) -> 3.675386e-07 | AG18: =IFERROR(I18/I$17,0) -> 6.4592379e-07 | AH18: =IFERROR(J18/J$17,0) -> 4.690669e-07 | AI18: =IFERROR(K18/K$17,0) -> 5.4333931e-07 | AK18: =IFERROR(H18-G18,0) -> 0.007024918 | AL18: =IFERROR(I18-H18,0) -> 0.027030539 | AM18: =IFERROR(J18-I18,0) -> -0.014123475 | AN18: =IFERROR(K18-J18,0) -> 0.0097992836 | AP18: =IFERROR((H18-G18)/G18,0) -> 0.28790647 | AQ18: =IFERROR((I18-H18)/H18,0) -> 0.86016259 | AR18: =IFERROR((J18-I18)/I18,0) -> -0.24161089 | AS18: =IFERROR((K18-J18)/J18,0) -> 0.22104321
A19: Planta, propiedad y equipo, neto | G19: =SUM(G20,G21) -> 2110 | H19: =SUM(H20,H21) -> 2112 | I19: =SUM(I20,I21) -> 2116 | J19: =SUM(J20,J21) -> 2537 | K19: =SUM(K20,K21) -> 2591 | L19: =+H19-G19 -> 2 | M19: =+I19-H19 -> 4 | N19: =+J19-I19 -> 421 | O19: =+K19-J19 -> 54 | AE19: =IFERROR(G19/G$17,0) -> 0.02545358 | AF19: =IFERROR(H19/H$17,0) -> 0.024701465 | AG19: =IFERROR(I19/I$17,0) -> 0.023381474 | AH19: =IFERROR(J19/J$17,0) -> 0.026843436 | AI19: =IFERROR(K19/K$17,0) -> 0.026007006 | AK19: =IFERROR(H19-G19,0) -> 2 | AL19: =IFERROR(I19-H19,0) -> 4 | AM19: =IFERROR(J19-I19,0) -> 421 | AN19: =IFERROR(K19-J19,0) -> 54 | AP19: =IFERROR((H19-G19)/G19,0) -> 0.0009478673 | AQ19: =IFERROR((I19-H19)/H19,0) -> 0.0018939394 | AR19: =IFERROR((J19-I19)/I19,0) -> 0.1989603 | AS19: =IFERROR((K19-J19)/J19,0) -> 0.021284982
A20: Inmovilizado material bruto | G20: 3869 | H20: 4070 | I20: 4071 | J20: 4510 | K20: 4461 | L20: =+H20-G20 -> 201 | M20: =+I20-H20 -> 1 | N20: =+J20-I20 -> 439 | O20: =+K20-J20 -> -49 | AD20: =+H20-G20 -> 201 | AE20: =IFERROR(G20/G$17,0) -> 0.04667294 | AF20: =IFERROR(H20/H$17,0) -> 0.047601782 | AG20: =IFERROR(I20/I$17,0) -> 0.044983922 | AH20: =IFERROR(J20/J$17,0) -> 0.047719313 | AI20: =IFERROR(K20/K$17,0) -> 0.044777018 | AK20: =IFERROR(H20-G20,0) -> 201 | AL20: =IFERROR(I20-H20,0) -> 1 | AM20: =IFERROR(J20-I20,0) -> 439 | AN20: =IFERROR(K20-J20,0) -> -49 | AP20: =IFERROR((H20-G20)/G20,0) -> 0.051951409 | AQ20: =IFERROR((I20-H20)/H20,0) -> 0.00024570025 | AR20: =IFERROR((J20-I20)/I20,0) -> 0.10783591 | AS20: =IFERROR((K20-J20)/J20,0) -> -0.010864745
A21: Amortización acumulada | G21: -1759 | H21: -1958 | I21: -1955 | J21: -1973 | K21: -1870 | L21: =+H21-G21 -> -199 | M21: =+I21-H21 -> 3 | N21: =+J21-I21 -> -18 | O21: =+K21-J21 -> 103 | AE21: =IFERROR(G21/G$17,0) -> -0.021219359 | AF21: =IFERROR(H21/H$17,0) -> -0.022900317 | AG21: =IFERROR(I21/I$17,0) -> -0.021602449 | AH21: =IFERROR(J21/J$17,0) -> -0.020875877 | AI21: =IFERROR(K21/K$17,0) -> -0.018770012 | AK21: =IFERROR(H21-G21,0) -> -199 | AL21: =IFERROR(I21-H21,0) -> 3 | AM21: =IFERROR(J21-I21,0) -> -18 | AN21: =IFERROR(K21-J21,0) -> 103 | AP21: =IFERROR((H21-G21)/G21,0) -> 0.11313246 | AQ21: =IFERROR((I21-H21)/H21,0) -> -0.0015321757 | AR21: =IFERROR((J21-I21)/I21,0) -> 0.0092071611 | AS21: =IFERROR((K21-J21)/J21,0) -> -0.052204764
A22: Inversiones a largo plazo | G22: 1843 | H22: 2136 | I22: 1921 | J22: 2545 | K22: 999 | AE22: =IFERROR(G22/G$17,0) -> 0.022232677 | AF22: =IFERROR(H22/H$17,0) -> 0.024982164 | AG22: =IFERROR(I22/I$17,0) -> 0.021226754 | AH22: =IFERROR(J22/J$17,0) -> 0.026928082 | AI22: =IFERROR(K22/K$17,0) -> 0.010027402 | AK22: =IFERROR(H22-G22,0) -> 293 | AL22: =IFERROR(I22-H22,0) -> -215 | AM22: =IFERROR(J22-I22,0) -> 624 | AN22: =IFERROR(K22-J22,0) -> -1546 | AP22: =IFERROR((H22-G22)/G22,0) -> 0.15897992 | AQ22: =IFERROR((I22-H22)/H22,0) -> -0.10065543 | AR22: =IFERROR((J22-I22)/I22,0) -> 0.32483082 | AS22: =IFERROR((K22-J22)/J22,0) -> -0.60746562
A23: Activos intangibles | G23: =SUM(G24,G25) -> 44742 | H23: =SUM(H24,H25) -> 44443 | I23: =SUM(I24,I25) -> 45898 | J23: =SUM(J24,J25) -> 47990 | K23: =SUM(K24,K25) -> 50124 | AE23: =IFERROR(G23/G$17,0) -> 0.53973654 | AF23: =IFERROR(H23/H$17,0) -> 0.51979509 | AG23: =IFERROR(I23/I$17,0) -> 0.50716583 | AH23: =IFERROR(J23/J$17,0) -> 0.50777158 | AI23: =IFERROR(K23/K$17,0) -> 0.50311663 | AK23: =IFERROR(H23-G23,0) -> -299 | AL23: =IFERROR(I23-H23,0) -> 1455 | AM23: =IFERROR(J23-I23,0) -> 2092 | AN23: =IFERROR(K23-J23,0) -> 2134 | AP23: =IFERROR((H23-G23)/G23,0) -> -0.0066827589 | AQ23: =IFERROR((I23-H23)/H23,0) -> 0.032738564 | AR23: =IFERROR((J23-I23)/I23,0) -> 0.045579328 | AS23: =IFERROR((K23-J23)/J23,0) -> 0.044467597
A24: Fondo de comercio | G24: 15958 | H24: 17787 | I24: 17997 | J24: 18941 | K24: 19879 | AE24: =IFERROR(G24/G$17,0) -> 0.19250627 | AF24: =IFERROR(H24/H$17,0) -> 0.20803265 | AG24: =IFERROR(I24/I$17,0) -> 0.19886408 | AH24: =IFERROR(J24/J$17,0) -> 0.20041053 | AI24: =IFERROR(K24/K$17,0) -> 0.19953426 | AK24: =IFERROR(H24-G24,0) -> 1829 | AL24: =IFERROR(I24-H24,0) -> 210 | AM24: =IFERROR(J24-I24,0) -> 944 | AN24: =IFERROR(K24-J24,0) -> 938 | AP24: =IFERROR((H24-G24)/G24,0) -> 0.11461336 | AQ24: =IFERROR((I24-H24)/H24,0) -> 0.011806375 | AR24: =IFERROR((J24-I24)/I24,0) -> 0.052453187 | AS24: =IFERROR((K24-J24)/J24,0) -> 0.049522201
A25: Otros intangibles, total | G25: 28784 | H25: 26656 | I25: 27901 | J25: 29049 | K25: 30245 | AE25: =IFERROR(G25/G$17,0) -> 0.34723026 | AF25: =IFERROR(H25/H$17,0) -> 0.31176244 | AG25: =IFERROR(I25/I$17,0) -> 0.30830175 | AH25: =IFERROR(J25/J$17,0) -> 0.30736105 | AI25: =IFERROR(K25/K$17,0) -> 0.30358236 | AK25: =IFERROR(H25-G25,0) -> -2128 | AL25: =IFERROR(I25-H25,0) -> 1245 | AM25: =IFERROR(J25-I25,0) -> 1148 | AN25: =IFERROR(K25-J25,0) -> 1196 | AP25: =IFERROR((H25-G25)/G25,0) -> -0.073929961 | AQ25: =IFERROR((I25-H25)/H25,0) -> 0.046706182 | AR25: =IFERROR((J25-I25)/I25,0) -> 0.041145479 | AS25: =IFERROR((K25-J25)/J25,0) -> 0.041171813
A26: División financiera, préstamos y arrendamientos a largo plazo | G26: - | H26: - | I26: - | J26: - | K26: - | AE26: =IFERROR(G26/G$17,0) -> 0 | AF26: =IFERROR(H26/H$17,0) -> 0 | AG26: =IFERROR(I26/I$17,0) -> 0 | AH26: =IFERROR(J26/J$17,0) -> 0 | AI26: =IFERROR(K26/K$17,0) -> 0 | AK26: =IFERROR(H26-G26,0) -> 0 | AL26: =IFERROR(I26-H26,0) -> 0 | AM26: =IFERROR(J26-I26,0) -> 0 | AN26: =IFERROR(K26-J26,0) -> 0 | AP26: =IFERROR((H26-G26)/G26,0) -> 0 | AQ26: =IFERROR((I26-H26)/H26,0) -> 0 | AR26: =IFERROR((J26-I26)/I26,0) -> 0 | AS26: =IFERROR((K26-J26)/J26,0) -> 0
A27: Total de otros activos | G27: =SUM(G28:G32) -> 6594 | H27: =SUM(H28:H32) -> 6605 | I27: =SUM(I28:I32) -> 7032 | J27: =SUM(J28:J32) -> 7406 | K27: =SUM(K28:K32) -> 8147 | AE27: =IFERROR(G27/G$17,0) -> 0.079545455 | AF27: =IFERROR(H27/H$17,0) -> 0.077250558 | AG27: =IFERROR(I27/I$17,0) -> 0.077702516 | AH27: =IFERROR(J27/J$17,0) -> 0.078361249 | AI27: =IFERROR(K27/K$17,0) -> 0.081775021 | AK27: =IFERROR(H27-G27,0) -> 11 | AL27: =IFERROR(I27-H27,0) -> 427 | AM27: =IFERROR(J27-I27,0) -> 374 | AN27: =IFERROR(K27-J27,0) -> 741 | AP27: =IFERROR((H27-G27)/G27,0) -> 0.0016681832 | AQ27: =IFERROR((I27-H27)/H27,0) -> 0.064647994 | AR27: =IFERROR((J27-I27)/I27,0) -> 0.053185438 | AS27: =IFERROR((K27-J27)/J27,0) -> 0.10005401
A28: Préstamos por cobrar a largo plazo | G28: - | H28: - | I28: - | J28: - | K28: - | AE28: =IFERROR(G28/G$17,0) -> 0 | AF28: =IFERROR(H28/H$17,0) -> 0 | AG28: =IFERROR(I28/I$17,0) -> 0 | AH28: =IFERROR(J28/J$17,0) -> 0 | AI28: =IFERROR(K28/K$17,0) -> 0 | AK28: =IFERROR(H28-G28,0) -> 0 | AL28: =IFERROR(I28-H28,0) -> 0 | AM28: =IFERROR(J28-I28,0) -> 0 | AN28: =IFERROR(K28-J28,0) -> 0 | AP28: =IFERROR((H28-G28)/G28,0) -> 0 | AQ28: =IFERROR((I28-H28)/H28,0) -> 0 | AR28: =IFERROR((J28-I28)/I28,0) -> 0 | AS28: =IFERROR((K28-J28)/J28,0) -> 0
A29: Cuentas por cobrar a largo plazo | G29: - | H29: - | I29: - | J29: - | K29: - | AE29: =IFERROR(G29/G$17,0) -> 0 | AF29: =IFERROR(H29/H$17,0) -> 0 | AG29: =IFERROR(I29/I$17,0) -> 0 | AH29: =IFERROR(J29/J$17,0) -> 0 | AI29: =IFERROR(K29/K$17,0) -> 0 | AK29: =IFERROR(H29-G29,0) -> 0 | AL29: =IFERROR(I29-H29,0) -> 0 | AM29: =IFERROR(J29-I29,0) -> 0 | AN29: =IFERROR(K29-J29,0) -> 0 | AP29: =IFERROR((H29-G29)/G29,0) -> 0 | AQ29: =IFERROR((I29-H29)/H29,0) -> 0 | AR29: =IFERROR((J29-I29)/I29,0) -> 0 | AS29: =IFERROR((K29-J29)/J29,0) -> 0
A30: Activos por impuestos diferidos a largo plazo | G30: 80 | H30: 87 | I30: 126 | J30: 140 | K30: 128 | AE30: =IFERROR(G30/G$17,0) -> 0.00096506466 | AF30: =IFERROR(H30/H$17,0) -> 0.001017532 | AG30: =IFERROR(I30/I$17,0) -> 0.0013922806 | AH30: =IFERROR(J30/J$17,0) -> 0.0014813091 | AI30: =IFERROR(K30/K$17,0) -> 0.0012847923 | AK30: =IFERROR(H30-G30,0) -> 7 | AL30: =IFERROR(I30-H30,0) -> 39 | AM30: =IFERROR(J30-I30,0) -> 14 | AN30: =IFERROR(K30-J30,0) -> -12 | AP30: =IFERROR((H30-G30)/G30,0) -> 0.0875 | AQ30: =IFERROR((I30-H30)/H30,0) -> 0.44827586 | AR30: =IFERROR((J30-I30)/I30,0) -> 0.11111111 | AS30: =IFERROR((K30-J30)/J30,0) -> -0.085714286
A31: Cargos diferidos a largo plazo | G31: - | H31: - | I31: - | J31: - | K31: - | AE31: =IFERROR(G31/G$17,0) -> 0 | AF31: =IFERROR(H31/H$17,0) -> 0 | AG31: =IFERROR(I31/I$17,0) -> 0 | AH31: =IFERROR(J31/J$17,0) -> 0 | AI31: =IFERROR(K31/K$17,0) -> 0 | AK31: =IFERROR(H31-G31,0) -> 0 | AL31: =IFERROR(I31-H31,0) -> 0 | AM31: =IFERROR(J31-I31,0) -> 0 | AN31: =IFERROR(K31-J31,0) -> 0 | AP31: =IFERROR((H31-G31)/G31,0) -> 0 | AQ31: =IFERROR((I31-H31)/H31,0) -> 0 | AR31: =IFERROR((J31-I31)/I31,0) -> 0 | AS31: =IFERROR((K31-J31)/J31,0) -> 0
A32: Total de otros activos a largo plazo | G32: 6514 | H32: 6518 | I32: 6906 | J32: 7266 | K32: 8019 | AE32: =IFERROR(G32/G$17,0) -> 0.07858039 | AF32: =IFERROR(H32/H$17,0) -> 0.076233027 | AG32: =IFERROR(I32/I$17,0) -> 0.076310235 | AH32: =IFERROR(J32/J$17,0) -> 0.07687994 | AI32: =IFERROR(K32/K$17,0) -> 0.080490229 | AK32: =IFERROR(H32-G32,0) -> 4 | AL32: =IFERROR(I32-H32,0) -> 388 | AM32: =IFERROR(J32-I32,0) -> 360 | AN32: =IFERROR(K32-J32,0) -> 753 | AP32: =IFERROR((H32-G32)/G32,0) -> 0.00061406202 | AQ32: =IFERROR((I32-H32)/H32,0) -> 0.059527462 | AR32: =IFERROR((J32-I32)/I32,0) -> 0.052128584 | AS32: =IFERROR((K32-J32)/J32,0) -> 0.10363336
A33: Total del pasivo corriente | G33: =SUM(G34,G35,G36,G37,G40) -> 15739 | H33: =SUM(H34,H35,H36,H37,H40) -> 20853 | I33: =SUM(I34,I35,I36,I37,I40) -> 23098 | J33: =SUM(J34,J35,J36,J37,J40) -> 26517 | K33: =SUM(K34,K35,K36,K37,K40) -> 35048 | AE33: =IFERROR(G33/G$17,0) -> 0.18986441 | AF33: =IFERROR(H33/H$17,0) -> 0.24389188 | AG33: =IFERROR(I33/I$17,0) -> 0.25522934 | AH33: =IFERROR(J33/J$17,0) -> 0.28057052 | AI33: =IFERROR(K33/K$17,0) -> 0.35179218 | AK33: =IFERROR(H33-G33,0) -> 5114 | AL33: =IFERROR(I33-H33,0) -> 2245 | AM33: =IFERROR(J33-I33,0) -> 3419 | AN33: =IFERROR(K33-J33,0) -> 8531 | AP33: =IFERROR((H33-G33)/G33,0) -> 0.32492534 | AQ33: =IFERROR((I33-H33)/H33,0) -> 0.10765837 | AR33: =IFERROR((J33-I33)/I33,0) -> 0.14802147 | AS33: =IFERROR((K33-J33)/J33,0) -> 0.32171814
A34: Total de cuentas por pagar | G34: 266 | H34: 340 | I34: 375 | J34: 479 | K34: 555 | AE34: =IFERROR(G34/G$17,0) -> 0.00320884 | AF34: =IFERROR(H34/H$17,0) -> 0.0039765617 | AG34: =IFERROR(I34/I$17,0) -> 0.0041436922 | AH34: =IFERROR(J34/J$17,0) -> 0.0050681931 | AI34: =IFERROR(K34/K$17,0) -> 0.005570779 | AK34: =IFERROR(H34-G34,0) -> 74 | AL34: =IFERROR(I34-H34,0) -> 35 | AM34: =IFERROR(J34-I34,0) -> 104 | AN34: =IFERROR(K34-J34,0) -> 76 | AP34: =IFERROR((H34-G34)/G34,0) -> 0.27819549 | AQ34: =IFERROR((I34-H34)/H34,0) -> 0.10294118 | AR34: =IFERROR((J34-I34)/I34,0) -> 0.27733333 | AS34: =IFERROR((K34-J34)/J34,0) -> 0.15866388
A35: Total de gastos devengados | G35: 3098 | H35: 4526 | I35: 4833 | J35: 5629 | K35: 6411 | AE35: =IFERROR(G35/G$17,0) -> 0.037372129 | AF35: =IFERROR(H35/H$17,0) -> 0.052935053 | AG35: =IFERROR(I35/I$17,0) -> 0.053403905 | AH35: =IFERROR(J35/J$17,0) -> 0.059559205 | AI35: =IFERROR(K35/K$17,0) -> 0.064350026 | AK35: =IFERROR(H35-G35,0) -> 1428 | AL35: =IFERROR(I35-H35,0) -> 307 | AM35: =IFERROR(J35-I35,0) -> 796 | AN35: =IFERROR(K35-J35,0) -> 782 | AP35: =IFERROR((H35-G35)/G35,0) -> 0.46094254 | AQ35: =IFERROR((I35-H35)/H35,0) -> 0.067830314 | AR35: =IFERROR((J35-I35)/I35,0) -> 0.16470101 | AS35: =IFERROR((K35-J35)/J35,0) -> 0.13892343
A36: Préstamos a corto plazo | G36: - | H36: - | I36: - | J36: - | K36: - | AE36: =IFERROR(G36/G$17,0) -> 0 | AF36: =IFERROR(H36/H$17,0) -> 0 | AG36: =IFERROR(I36/I$17,0) -> 0 | AH36: =IFERROR(J36/J$17,0) -> 0 | AI36: =IFERROR(K36/K$17,0) -> 0 | AK36: =IFERROR(H36-G36,0) -> 0 | AL36: =IFERROR(I36-H36,0) -> 0 | AM36: =IFERROR(J36-I36,0) -> 0 | AN36: =IFERROR(K36-J36,0) -> 0 | AP36: =IFERROR((H36-G36)/G36,0) -> 0 | AQ36: =IFERROR((I36-H36)/H36,0) -> 0 | AR36: =IFERROR((J36-I36)/I36,0) -> 0 | AS36: =IFERROR((K36-J36)/J36,0) -> 0
A37: Parte actual de la deuda a largo plazo/arrendamientos | G37: =SUM(G38,G39) -> 1102 | H37: =SUM(H38,H39) -> 2348 | I37: =SUM(I38,I39) -> 106 | J37: =SUM(J38,J39) -> 150 | K37: =SUM(K38,K39) -> 5719 | AE37: =IFERROR(G37/G$17,0) -> 0.013293766 | AF37: =IFERROR(H37/H$17,0) -> 0.027461667 | AG37: =IFERROR(I37/I$17,0) -> 0.0011712837 | AH37: =IFERROR(J37/J$17,0) -> 0.0015871168 | AI37: =IFERROR(K37/K$17,0) -> 0.057404117 | AK37: =IFERROR(H37-G37,0) -> 1246 | AL37: =IFERROR(I37-H37,0) -> -2242 | AM37: =IFERROR(J37-I37,0) -> 44 | AN37: =IFERROR(K37-J37,0) -> 5569 | AP37: =IFERROR((H37-G37)/G37,0) -> 1.1306715 | AQ37: =IFERROR((I37-H37)/H37,0) -> -0.9548552 | AR37: =IFERROR((J37-I37)/I37,0) -> 0.41509434 | AS37: =IFERROR((K37-J37)/J37,0) -> 37.126667
A38: Parte actual de la deuda a largo plazo | G38: 999 | H38: 2250 | I38: - | J38: - | K38: 5569 | AE38: =IFERROR(G38/G$17,0) -> 0.012051245 | AF38: =IFERROR(H38/H$17,0) -> 0.026315482 | AG38: =IFERROR(I38/I$17,0) -> 0 | AH38: =IFERROR(J38/J$17,0) -> 0 | AI38: =IFERROR(K38/K$17,0) -> 0.055898501 | AK38: =IFERROR(H38-G38,0) -> 1251 | AL38: =IFERROR(I38-H38,0) -> 0 | AM38: =IFERROR(J38-I38,0) -> 0 | AN38: =IFERROR(K38-J38,0) -> 0 | AP38: =IFERROR((H38-G38)/G38,0) -> 1.2522523 | AQ38: =IFERROR((I38-H38)/H38,0) -> 0 | AR38: =IFERROR((J38-I38)/I38,0) -> 0 | AS38: =IFERROR((K38-J38)/J38,0) -> 0
A39: Parte actual de arrendamientos | G39: 103 | H39: 98 | I39: 106 | J39: 150 | K39: 150 | AE39: =IFERROR(G39/G$17,0) -> 0.0012425207 | AF39: =IFERROR(H39/H$17,0) -> 0.0011461854 | AG39: =IFERROR(I39/I$17,0) -> 0.0011712837 | AH39: =IFERROR(J39/J$17,0) -> 0.0015871168 | AI39: =IFERROR(K39/K$17,0) -> 0.0015056159 | AK39: =IFERROR(H39-G39,0) -> -5 | AL39: =IFERROR(I39-H39,0) -> 8 | AM39: =IFERROR(J39-I39,0) -> 44 | AN39: =IFERROR(K39-J39,0) -> 0 | AP39: =IFERROR((H39-G39)/G39,0) -> -0.048543689 | AQ39: =IFERROR((I39-H39)/H39,0) -> 0.081632653 | AR39: =IFERROR((J39-I39)/I39,0) -> 0.41509434 | AS39: =IFERROR((K39-J39)/J39,0) -> 0
A40: Total de otros pasivos corrientes | G40: =SUM(G41,G42,G43) -> 11273 | H40: =SUM(H41,H42,H43) -> 13639 | I40: =SUM(I41,I42,I43) -> 17784 | J40: =SUM(J41,J42,J43) -> 20259 | K40: =SUM(K41,K42,K43) -> 22363 | AE40: =IFERROR(G40/G$17,0) -> 0.13598967 | AF40: =IFERROR(H40/H$17,0) -> 0.1595186 | AG40: =IFERROR(I40/I$17,0) -> 0.19651046 | AH40: =IFERROR(J40/J$17,0) -> 0.214356 | AI40: =IFERROR(K40/K$17,0) -> 0.22446726 | AK40: =IFERROR(H40-G40,0) -> 2366 | AL40: =IFERROR(I40-H40,0) -> 4145 | AM40: =IFERROR(J40-I40,0) -> 2475 | AN40: =IFERROR(K40-J40,0) -> 2104 | AP40: =IFERROR((H40-G40)/G40,0) -> 0.20988202 | AQ40: =IFERROR((I40-H40)/H40,0) -> 0.30390791 | AR40: =IFERROR((J40-I40)/I40,0) -> 0.13917004 | AS40: =IFERROR((K40-J40)/J40,0) -> 0.10385508
...

Sheet PyG
A1: ESTADO DE RESULTADO | G1: 2021 | H1: 2022 | I1: 2023 | J1: 2024 | K1: 2025 | AA1: ANÁLISIS VERTICAL (% de Ingresos Totales) | AG1: ANÁLISIS HORIZONTAL - Variación absoluta | AL1: ANÁLISIS HORIZONTAL - Variación %
G2: 46295 | H2: 46295 | I2: 46295 | J2: 46295 | K2: 46295 | AA2: 2021 | AB2: 2022 | AC2: 2023 | AD2: 2024 | AE2: 2025 | AG2: 2022/2021 | AH2: 2023/2022 | AI2: 2024/2023 | AJ2: 2025/2024 | AL2: 2022/2021 | AM2: 2023/2022 | AN2: 2024/2023 | AO2: 2025/2024
A3: Ingresos totales | G3: 24105 | H3: 29310 | I3: 32653 | J3: 35926 | K3: 40000 | AA3: =IFERROR(G3/G$3,0) -> 1 | AB3: =IFERROR(H3/H$3,0) -> 1 | AC3: =IFERROR(I3/I$3,0) -> 1 | AD3: =IFERROR(J3/J$3,0) -> 1 | AE3: =IFERROR(K3/K$3,0) -> 1 | AG3: =IFERROR(H3-G3,0) -> 5205 | AH3: =IFERROR(I3-H3,0) -> 3343 | AI3: =IFERROR(J3-I3,0) -> 3273 | AJ3: =IFERROR(K3-J3,0) -> 4074 | AL3: =IFERROR((H3-G3)/G3,0) -> 0.2159303 | AM3: =IFERROR((I3-H3)/H3,0) -> 0.11405664 | AN3: =IFERROR((J3-I3)/I3,0) -> 0.10023581 | AO3: =IFERROR((K3-J3)/J3,0) -> 0.11339977
A4: Crecimiento de los ingresos totales | G4: 0.1034 | H4: =IFERROR((H3-G3)/G3,0) -> 0.2159303 | I4: =IFERROR((I3-H3)/H3,0) -> 0.11405664 | J4: =IFERROR((J3-I3)/I3,0) -> 0.10023581 | K4: =IFERROR((K3-J3)/J3,0) -> 0.11339977 | AA4: =IFERROR(G4/G$3,0) -> 4.2895665e-06 | AB4: =IFERROR(H4/H$3,0) -> 7.3671206e-06 | AC4: =IFERROR(I4/I$3,0) -> 3.492991e-06 | AD4: =IFERROR(J4/J$3,0) -> 2.7900633e-06 | AE4: =IFERROR(K4/K$3,0) -> 2.8349942e-06 | AG4: =IFERROR(H4-G4,0) -> 0.1125303 | AH4: =IFERROR(I4-H4,0) -> -0.10187367 | AI4: =IFERROR(J4-I4,0) -> -0.013820823 | AJ4: =IFERROR(K4-J4,0) -> 0.013163953 | AL4: =IFERROR((H4-G4)/G4,0) -> 1.0883008 | AM4: =IFERROR((I4-H4)/H4,0) -> -0.47178959 | AN4: =IFERROR((J4-I4)/I4,0) -> -0.12117509 | AO4: =IFERROR((K4-J4)/J4,0) -> 0.13132984
A5: Coste de los ingresos | G5: 730 | H5: 743 | I5: 736 | J5: 778 | K5: 894 | AA5: =IFERROR(G5/G$3,0) -> 0.030284173 | AB5: =IFERROR(H5/H$3,0) -> 0.02534971 | AC5: =IFERROR(I5/I$3,0) -> 0.022540042 | AD5: =IFERROR(J5/J$3,0) -> 0.021655625 | AE5: =IFERROR(K5/K$3,0) -> 0.02235 | AG5: =IFERROR(H5-G5,0) -> 13 | AH5: =IFERROR(I5-H5,0) -> -7 | AI5: =IFERROR(J5-I5,0) -> 42 | AJ5: =IFERROR(K5-J5,0) -> 116 | AL5: =IFERROR((H5-G5)/G5,0) -> 0.017808219 | AM5: =IFERROR((I5-H5)/H5,0) -> -0.0094212651 | AN5: =IFERROR((J5-I5)/I5,0) -> 0.057065217 | AO5: =IFERROR((K5-J5)/J5,0) -> 0.14910026
A6: Beneficio bruto | G6: =IFERROR(G3-G5,0) -> 23375 | H6: =IFERROR(H3-H5,0) -> 28567 | I6: =IFERROR(I3-I5,0) -> 31917 | J6: =IFERROR(J3-J5,0) -> 35148 | K6: =IFERROR(K3-K5,0) -> 39106 | AA6: =IFERROR(G6/G$3,0) -> 0.96971583 | AB6: =IFERROR(H6/H$3,0) -> 0.97465029 | AC6: =IFERROR(I6/I$3,0) -> 0.97745996 | AD6: =IFERROR(J6/J$3,0) -> 0.97834437 | AE6: =IFERROR(K6/K$3,0) -> 0.97765 | AG6: =IFERROR(H6-G6,0) -> 5192 | AH6: =IFERROR(I6-H6,0) -> 3350 | AI6: =IFERROR(J6-I6,0) -> 3231 | AJ6: =IFERROR(K6-J6,0) -> 3958 | AL6: =IFERROR((H6-G6)/G6,0) -> 0.22211765 | AM6: =IFERROR((I6-H6)/H6,0) -> 0.11726818 | AN6: =IFERROR((J6-I6)/I6,0) -> 0.10123132 | AO6: =IFERROR((K6-J6)/J6,0) -> 0.11260954
A7: Crecimiento del beneficio bruto | G7: 0.1068 | H7: =IFERROR((H6-G6)/G6,0) -> 0.22211765 | I7: =IFERROR((I6-H6)/H6,0) -> 0.11726818 | J7: =IFERROR((J6-I6)/I6,0) -> 0.10123132 | K7: =IFERROR((K6-J6)/J6,0) -> 0.11260954 | AA7: =IFERROR(G7/G$3,0) -> 4.4306161e-06 | AB7: =IFERROR(H7/H$3,0) -> 7.5782206e-06 | AC7: =IFERROR(I7/I$3,0) -> 3.5913446e-06 | AD7: =IFERROR(J7/J$3,0) -> 2.8177732e-06 | AE7: =IFERROR(K7/K$3,0) -> 2.8152384e-06 | AG7: =IFERROR(H7-G7,0) -> 0.11531765 | AH7: =IFERROR(I7-H7,0) -> -0.10484947 | AI7: =IFERROR(J7-I7,0) -> -0.016036858 | AJ7: =IFERROR(K7-J7,0) -> 0.011378218 | AL7: =IFERROR((H7-G7)/G7,0) -> 1.0797532 | AM7: =IFERROR((I7-H7)/H7,0) -> -0.47204476 | AN7: =IFERROR((J7-I7)/I7,0) -> -0.13675371 | AO7: =IFERROR((K7-J7)/J7,0) -> 0.1123982
A8: Margen de beneficio bruto % | G8: =IFERROR(G6/G3,0) -> 0.96971583 | H8: =IFERROR(H6/H3,0) -> 0.97465029 | I8: =IFERROR(I6/I3,0) -> 0.97745996 | J8: =IFERROR(J6/J3,0) -> 0.97834437 | K8: =IFERROR(K6/K3,0) -> 0.97765 | AA8: =IFERROR(G8/G$3,0) -> 4.0228825e-05 | AB8: =IFERROR(H8/H$3,0) -> 3.3253166e-05 | AC8: =IFERROR(I8/I$3,0) -> 2.9934767e-05 | AD8: =IFERROR(J8/J$3,0) -> 2.723221e-05 | AE8: =IFERROR(K8/K$3,0) -> 2.444125e-05 | AG8: =IFERROR(H8-G8,0) -> 0.0049344634 | AH8: =IFERROR(I8-H8,0) -> 0.0028096677 | AI8: =IFERROR(J8-I8,0) -> 0.00088441681 | AJ8: =IFERROR(K8-J8,0) -> -0.00069437455 | AL8: =IFERROR((H8-G8)/G8,0) -> 0.0050885664 | AM8: =IFERROR((I8-H8)/H8,0) -> 0.0028827445 | AN8: =IFERROR((J8-I8)/I8,0) -> 0.0009048113 | AO8: =IFERROR((K8-J8)/J8,0) -> -0.00070974451
A9: Total de otros gastos operativos | G9: 7568 | H9: 8886 | I9: 9990 | J9: 11152 | K9: 12298 | AA9: =IFERROR(G9/G$3,0) -> 0.31395976 | AB9: =IFERROR(H9/H$3,0) -> 0.30317298 | AC9: =IFERROR(I9/I$3,0) -> 0.30594432 | AD9: =IFERROR(J9/J$3,0) -> 0.31041585 | AE9: =IFERROR(K9/K$3,0) -> 0.30745 | AG9: =IFERROR(H9-G9,0) -> 1318 | AH9: =IFERROR(I9-H9,0) -> 1104 | AI9: =IFERROR(J9-I9,0) -> 1162 | AJ9: =IFERROR(K9-J9,0) -> 1146 | AL9: =IFERROR((H9-G9)/G9,0) -> 0.17415433 | AM9: =IFERROR((I9-H9)/H9,0) -> 0.12424038 | AN9: =IFERROR((J9-I9)/I9,0) -> 0.11631632 | AO9: =IFERROR((K9-J9)/J9,0) -> 0.10276184
A10: Crecmiento total de otros gastos operativos | G10: 0.0821 | H10: =IFERROR((H9-G9)/G9,0) -> 0.17415433 | I10: =IFERROR((I9-H9)/H9,0) -> 0.12424038 | J10: =IFERROR((J9-I9)/I9,0) -> 0.11631632 | K10: =IFERROR((K9-J9)/J9,0) -> 0.10276184 | AA10: =IFERROR(G10/G$3,0) -> 3.4059324e-06 | AB10: =IFERROR(H10/H$3,0) -> 5.941806e-06 | AC10: =IFERROR(I10/I$3,0) -> 3.8048687e-06 | AD10: =IFERROR(J10/J$3,0) -> 3.237664e-06 | AE10: =IFERROR(K10/K$3,0) -> 2.5690459e-06 | AG10: =IFERROR(H10-G10,0) -> 0.092054334 | AH10: =IFERROR(I10-H10,0) -> -0.049913956 | AI10: =IFERROR(J10-I10,0) -> -0.0079240618 | AJ10: =IFERROR(K10-J10,0) -> -0.01355448 | AL10: =IFERROR((H10-G10)/G10,0) -> 1.1212465 | AM10: =IFERROR((I10-H10)/H10,0) -> -0.2866076 | AN10: =IFERROR((J10-I10)/I10,0) -> -0.063780084 | AO10: =IFERROR((K10-J10)/J10,0) -> -0.1165312
A11: Gastos de I+D | G11: - | H11: - | I11: - | J11: - | K11: - | AA11: =IFERROR(G11/G$3,0) -> 0 | AB11: =IFERROR(H11/H$3,0) -> 0 | AC11: =IFERROR(I11/I$3,0) -> 0 | AD11: =IFERROR(J11/J$3,0) -> 0 | AE11: =IFERROR(K11/K$3,0) -> 0 | AG11: =IFERROR(H11-G11,0) -> 0 | AH11: =IFERROR(I11-H11,0) -> 0 | AI11: =IFERROR(J11-I11,0) -> 0 | AJ11: =IFERROR(K11-J11,0) -> 0 | AL11: =IFERROR((H11-G11)/G11,0) -> 0 | AM11: =IFERROR((I11-H11)/H11,0) -> 0 | AN11: =IFERROR((J11-I11)/I11,0) -> 0 | AO11: =IFERROR((K11-J11)/J11,0) -> 0
A12: Gastos de venta, generales y administrativos | G12: 6612 | H12: 8025 | I12: 9047 | J12: 10118 | K12: 11078 | AA12: =IFERROR(G12/G$3,0) -> 0.27429994 | AB12: =IFERROR(H12/H$3,0) -> 0.27379734 | AC12: =IFERROR(I12/I$3,0) -> 0.27706489 | AD12: =IFERROR(J12/J$3,0) -> 0.28163447 | AE12: =IFERROR(K12/K$3,0) -> 0.27695 | AG12: =IFERROR(H12-G12,0) -> 1413 | AH12: =IFERROR(I12-H12,0) -> 1022 | AI12: =IFERROR(J12-I12,0) -> 1071 | AJ12: =IFERROR(K12-J12,0) -> 960 | AL12: =IFERROR((H12-G12)/G12,0) -> 0.21370236 | AM12: =IFERROR((I12-H12)/H12,0) -> 0.12735202 | AN12: =IFERROR((J12-I12)/I12,0) -> 0.11838178 | AO12: =IFERROR((K12-J12)/J12,0) -> 0.094880411
A13: Otros gastos operativos | G13: 152 | H13: - | I13: - | J13: - | K13: - | AA13: =IFERROR(G13/G$3,0) -> 0.0063057457 | AB13: =IFERROR(H13/H$3,0) -> 0 | AC13: =IFERROR(I13/I$3,0) -> 0 | AD13: =IFERROR(J13/J$3,0) -> 0 | AE13: =IFERROR(K13/K$3,0) -> 0 | AG13: =IFERROR(H13-G13,0) -> 0 | AH13: =IFERROR(I13-H13,0) -> 0 | AI13: =IFERROR(J13-I13,0) -> 0 | AJ13: =IFERROR(K13-J13,0) -> 0 | AL13: =IFERROR((H13-G13)/G13,0) -> 0 | AM13: =IFERROR((I13-H13)/H13,0) -> 0 | AN13: =IFERROR((J13-I13)/I13,0) -> 0 | AO13: =IFERROR((K13-J13)/J13,0) -> 0
A14: Margen neto | G14: =IFERROR(G6-G9,0) -> 15807 | H14: =IFERROR(H6-H9,0) -> 19681 | I14: =IFERROR(I6-I9,0) -> 21927 | J14: =IFERROR(J6-J9,0) -> 23996 | K14: =IFERROR(K6-K9,0) -> 26808 | AA14: =IFERROR(G14/G$3,0) -> 0.65575607 | AB14: =IFERROR(H14/H$3,0) -> 0.67147731 | AC14: =IFERROR(I14/I$3,0) -> 0.67151563 | AD14: =IFERROR(J14/J$3,0) -> 0.66792852 | AE14: =IFERROR(K14/K$3,0) -> 0.6702 | AG14: =IFERROR(H14-G14,0) -> 3874 | AH14: =IFERROR(I14-H14,0) -> 2246 | AI14: =IFERROR(J14-I14,0) -> 2069 | AJ14: =IFERROR(K14-J14,0) -> 2812 | AL14: =IFERROR((H14-G14)/G14,0) -> 0.24508129 | AM14: =IFERROR((I14-H14)/H14,0) -> 0.11412022 | AN14: =IFERROR((J14-I14)/I14,0) -> 0.094358553 | AO14: =IFERROR((K14-J14)/J14,0) -> 0.1171862
A15: Crecimiento del margen neto | G15: 0.1191 | H15: =IFERROR((H14-G14)/G14,0) -> 0.24508129 | I15: =IFERROR((I14-H14)/H14,0) -> 0.11412022 | J15: =IFERROR((J14-I14)/I14,0) -> 0.094358553 | K15: =IFERROR((K14-J14)/J14,0) -> 0.1171862 | AA15: =IFERROR(G15/G$3,0) -> 4.9408836e-06 | AB15: =IFERROR(H15/H$3,0) -> 8.3616954e-06 | AC15: =IFERROR(I15/I$3,0) -> 3.4949382e-06 | AD15: =IFERROR(J15/J$3,0) -> 2.6264698e-06 | AE15: =IFERROR(K15/K$3,0) -> 2.9296549e-06 | AG15: =IFERROR(H15-G15,0) -> 0.12598129 | AH15: =IFERROR(I15-H15,0) -> -0.13096108 | AI15: =IFERROR(J15-I15,0) -> -0.019761664 | AJ15: =IFERROR(K15-J15,0) -> 0.022827644 | AL15: =IFERROR((H15-G15)/G15,0) -> 1.0577774 | AM15: =IFERROR((I15-H15)/H15,0) -> -0.5343577 | AN15: =IFERROR((J15-I15)/I15,0) -> -0.17316532 | AO15: =IFERROR((K15-J15)/J15,0) -> 0.24192448
A16: Margen EBIT % | G16: =IFERROR(G14/G3,0) -> 0.65575607 | H16: =IFERROR(H14/H3,0) -> 0.67147731 | I16: =IFERROR(I14/I3,0) -> 0.67151563 | J16: =IFERROR(J14/J3,0) -> 0.66792852 | K16: =IFERROR(K14/K3,0) -> 0.6702 | AA16: =IFERROR(G16/G$3,0) -> 2.7204151e-05 | AB16: =IFERROR(H16/H$3,0) -> 2.2909495e-05 | AC16: =IFERROR(I16/I$3,0) -> 2.0565205e-05 | AD16: =IFERROR(J16/J$3,0) -> 1.8591786e-05 | AE16: =IFERROR(K16/K$3,0) -> 1.6755e-05 | AG16: =IFERROR(H16-G16,0) -> 0.015721244 | AH16: =IFERROR(I16-H16,0) -> 3.8322594e-05 | AI16: =IFERROR(J16-I16,0) -> -0.0035871144 | AJ16: =IFERROR(K16-J16,0) -> 0.0022714803 | AL16: =IFERROR((H16-G16)/G16,0) -> 0.023974226 | AM16: =IFERROR((I16-H16)/H16,0) -> 5.7072061e-05 | AN16: =IFERROR((J16-I16)/I16,0) -> -0.0053418181 | AO16: =IFERROR((K16-J16)/J16,0) -> 0.0034007835
A17: Gastos netos por intereses | G17: =IFERROR(SUM(G19,G20),0) -> -513 | H17: =IFERROR(SUM(H19,H20),0) -> -469 | I17: =IFERROR(SUM(I19,I20),0) -> 101 | J17: =IFERROR(SUM(J19,J20),0) -> 351 | K17: =IFERROR(SUM(K19,K20),0) -> 202 | AA17: =IFERROR(G17/G$3,0) -> -0.021281892 | AB17: =IFERROR(H17/H$3,0) -> -0.016001365 | AC17: =IFERROR(I17/I$3,0) -> 0.0030931308 | AD17: =IFERROR(J17/J$3,0) -> 0.0097700829 | AE17: =IFERROR(K17/K$3,0) -> 0.00505 | AG17: =IFERROR(H17-G17,0) -> 44 | AH17: =IFERROR(I17-H17,0) -> 570 | AI17: =IFERROR(J17-I17,0) -> 250 | AJ17: =IFERROR(K17-J17,0) -> -149 | AL17: =IFERROR((H17-G17)/G17,0) -> -0.085769981 | AM17: =IFERROR((I17-H17)/H17,0) -> -1.2153518 | AN17: =IFERROR((J17-I17)/I17,0) -> 2.4752475 | AO17: =IFERROR((K17-J17)/J17,0) -> -0.42450142
A18: Crecimiento de gastos netos por intereses | G18: -0.1766 | H18: =IFERROR((H17-G17)/G17,0) -> -0.085769981 | I18: =IFERROR((I17-H17)/H17,0) -> -1.2153518 | J18: =IFERROR((J17-I17)/I17,0) -> 2.4752475 | K18: =IFERROR((K17-J17)/J17,0) -> -0.42450142 | AA18: =IFERROR(G18/G$3,0) -> -7.3262809e-06 | AB18: =IFERROR(H18/H$3,0) -> -2.9263044e-06 | AC18: =IFERROR(I18/I$3,0) -> -3.7220219e-05 | AD18: =IFERROR(J18/J$3,0) -> 6.88985e-05 | AE18: =IFERROR(K18/K$3,0) -> -1.0612536e-05 | AG18: =IFERROR(H18-G18,0) -> 0.090830019 | AH18: =IFERROR(I18-H18,0) -> -1.1295818 | AI18: =IFERROR(J18-I18,0) -> 3.6905993 | AJ18: =IFERROR(K18-J18,0) -> -2.8997489 | AL18: =IFERROR((H18-G18)/G18,0) -> -0.51432627 | AM18: =IFERROR((I18-H18)/H18,0) -> 13.169897 | AN18: =IFERROR((J18-I18)/I18,0) -> -3.036651 | AO18: =IFERROR((K18-J18)/J18,0) -> -1.1714986
A19: Total de gastos de intereses | G19: -513 | H19: -538 | I19: -644 | J19: -641 | K19: -589 | AA19: =IFERROR(G19/G$3,0) -> -0.021281892 | AB19: =IFERROR(H19/H$3,0) -> -0.01835551 | AC19: =IFERROR(I19/I$3,0) -> -0.019722537 | AD19: =IFERROR(J19/J$3,0) -> -0.017842231 | AE19: =IFERROR(K19/K$3,0) -> -0.014725 | AG19: =IFERROR(H19-G19,0) -> -25 | AH19: =IFERROR(I19-H19,0) -> -106 | AI19: =IFERROR(J19-I19,0) -> 3 | AJ19: =IFERROR(K19-J19,0) -> 52 | AL19: =IFERROR((H19-G19)/G19,0) -> 0.048732943 | AM19: =IFERROR((I19-H19)/H19,0) -> 0.19702602 | AN19: =IFERROR((J19-I19)/I19,0) -> -0.0046583851 | AO19: =IFERROR((K19-J19)/J19,0) -> -0.081123245
A20: Ingresos por intereses e inversiones | G20: - | H20: 69 | I20: 745 | J20: 992 | K20: 791 | AA20: =IFERROR(G20/G$3,0) -> 0 | AB20: =IFERROR(H20/H$3,0) -> 0.0023541453 | AC20: =IFERROR(I20/I$3,0) -> 0.022815668 | AD20: =IFERROR(J20/J$3,0) -> 0.027612314 | AE20: =IFERROR(K20/K$3,0) -> 0.019775 | AG20: =IFERROR(H20-G20,0) -> 0 | AH20: =IFERROR(I20-H20,0) -> 676 | AI20: =IFERROR(J20-I20,0) -> 247 | AJ20: =IFERROR(K20-J20,0) -> -201 | AL20: =IFERROR((H20-G20)/G20,0) -> 0 | AM20: =IFERROR((I20-H20)/H20,0) -> 9.7971014 | AN20: =IFERROR((J20-I20)/I20,0) -> 0.33154362 | AO20: =IFERROR((K20-J20)/J20,0) -> -0.20262097
A21: Total de otros gastos no operativos | G21: 25 | H21: 88 | I21: 18 | J21: 14 | K21: 49 | AA21: =IFERROR(G21/G$3,0) -> 0.0010371292 | AB21: =IFERROR(H21/H$3,0) -> 0.0030023883 | AC21: =IFERROR(I21/I$3,0) -> 0.00055125103 | AD21: =IFERROR(J21/J$3,0) -> 0.00038968992 | AE21: =IFERROR(K21/K$3,0) -> 0.001225 | AG21: =IFERROR(H21-G21,0) -> 63 | AH21: =IFERROR(I21-H21,0) -> -70 | AI21: =IFERROR(J21-I21,0) -> -4 | AJ21: =IFERROR(K21-J21,0) -> 35 | AL21: =IFERROR((H21-G21)/G21,0) -> 2.52 | AM21: =IFERROR((I21-H21)/H21,0) -> -0.79545455 | AN21: =IFERROR((J21-I21)/I21,0) -> -0.22222222 | AO21: =IFERROR((K21-J21)/J21,0) -> 2.5
A22: EBT excepto elementos no habituales | G22: =IFERROR(SUM(G14,G17,G21),0) -> 15319 | H22: =IFERROR(SUM(H14,H17,H21),0) -> 19300 | I22: =IFERROR(SUM(I14,I17,I21),0) -> 22046 | J22: =IFERROR(SUM(J14,J17,J21),0) -> 24361 | K22: =IFERROR(SUM(K14,K17,K21),0) -> 27059 | AA22: =IFERROR(G22/G$3,0) -> 0.6355113 | AB22: =IFERROR(H22/H$3,0) -> 0.65847834 | AC22: =IFERROR(I22/I$3,0) -> 0.67516002 | AD22: =IFERROR(J22/J$3,0) -> 0.67808829 | AE22: =IFERROR(K22/K$3,0) -> 0.676475 | AG22: =IFERROR(H22-G22,0) -> 3981 | AH22: =IFERROR(I22-H22,0) -> 2746 | AI22: =IFERROR(J22-I22,0) -> 2315 | AJ22: =IFERROR(K22-J22,0) -> 2698 | AL22: =IFERROR((H22-G22)/G22,0) -> 0.25987336 | AM22: =IFERROR((I22-H22)/H22,0) -> 0.14227979 | AN22: =IFERROR((J22-I22)/I22,0) -> 0.10500771 | AO22: =IFERROR((K22-J22)/J22,0) -> 0.11075079
A23: Ganancia (pérdida) de la venta de activos | G23: - | H23: - | I23: - | J23: - | K23: - | AA23: =IFERROR(G23/G$3,0) -> 0 | AB23: =IFERROR(H23/H$3,0) -> 0 | AC23: =IFERROR(I23/I$3,0) -> 0 | AD23: =IFERROR(J23/J$3,0) -> 0 | AE23: =IFERROR(K23/K$3,0) -> 0 | AG23: =IFERROR(H23-G23,0) -> 0 | AH23: =IFERROR(I23-H23,0) -> 0 | AI23: =IFERROR(J23-I23,0) -> 0 | AJ23: =IFERROR(K23-J23,0) -> 0 | AL23: =IFERROR((H23-G23)/G23,0) -> 0 | AM23: =IFERROR((I23-H23)/H23,0) -> 0 | AN23: =IFERROR((J23-I23)/I23,0) -> 0 | AO23: =IFERROR((K23-J23)/J23,0) -> 0
A24: Total de otras partidas no habituales | G24: -3 | H24: -868 | I24: -927 | J24: -401 | K24: -2601 | AA24: =IFERROR(G24/G$3,0) -> -0.00012445551 | AB24: =IFERROR(H24/H$3,0) -> -0.029614466 | AC24: =IFERROR(I24/I$3,0) -> -0.028389428 | AD24: =IFERROR(J24/J$3,0) -> -0.011161833 | AE24: =IFERROR(K24/K$3,0) -> -0.065025 | AG24: =IFERROR(H24-G24,0) -> -865 | AH24: =IFERROR(I24-H24,0) -> -59 | AI24: =IFERROR(J24-I24,0) -> 526 | AJ24: =IFERROR(K24-J24,0) -> -2200 | AL24: =IFERROR((H24-G24)/G24,0) -> 288.33333 | AM24: =IFERROR((I24-H24)/H24,0) -> 0.06797235 | AN24: =IFERROR((J24-I24)/I24,0) -> -0.56742179 | AO24: =IFERROR((K24-J24)/J24,0) -> 5.4862843
A25: EBT incluyendo las partidas inusuales | G25: 16063 | H25: 18136 | I25: 21037 | J25: 23916 | K25: 24194 | AA25: =IFERROR(G25/G$3,0) -> 0.66637627 | AB25: =IFERROR(H25/H$3,0) -> 0.61876493 | AC25: =IFERROR(I25/I$3,0) -> 0.64425933 | AD25: =IFERROR(J25/J$3,0) -> 0.66570172 | AE25: =IFERROR(K25/K$3,0) -> 0.60485 | AG25: =IFERROR(H25-G25,0) -> 2073 | AH25: =IFERROR(I25-H25,0) -> 2901 | AI25: =IFERROR(J25-I25,0) -> 2879 | AJ25: =IFERROR(K25-J25,0) -> 278 | AL25: =IFERROR((H25-G25)/G25,0) -> 0.12905435 | AM25: =IFERROR((I25-H25)/H25,0) -> 0.15995809 | AN25: =IFERROR((J25-I25)/I25,0) -> 0.13685411 | AO25: =IFERROR((K25-J25)/J25,0) -> 0.011624017
A26: Crecimiento del EBT incluidas las partidas inusuales | G26: 0.1648 | H26: =IFERROR((H25-G25)/G25,0) -> 0.12905435 | I26: =IFERROR((I25-H25)/H25,0) -> 0.15995809 | J26: =IFERROR((J25-I25)/I25,0) -> 0.13685411 | K26: =IFERROR((K25-J25)/J25,0) -> 0.011624017 | AA26: =IFERROR(G26/G$3,0) -> 6.8367559e-06 | AB26: =IFERROR(H26/H$3,0) -> 4.4030825e-06 | AC26: =IFERROR(I26/I$3,0) -> 4.8987258e-06 | AD26: =IFERROR(J26/J$3,0) -> 3.8093335e-06 | AE26: =IFERROR(K26/K$3,0) -> 2.9060043e-07 | AG26: =IFERROR(H26-G26,0) -> -0.035745651 | AH26: =IFERROR(I26-H26,0) -> 0.030903746 | AI26: =IFERROR(J26-I26,0) -> -0.02310398 | AJ26: =IFERROR(K26-J26,0) -> -0.1252301 | AL26: =IFERROR((H26-G26)/G26,0) -> -0.21690323 | AM26: =IFERROR((I26-H26)/H26,0) -> 0.23946303 | AN26: =IFERROR((J26-I26)/I26,0) -> -0.14443771 | AO26: =IFERROR((K26-J26)/J26,0) -> -0.91506271
A27: Margen del EBT incluidas las partidas inusuales | G27: =IFERROR(G25/G3,0) -> 0.66637627 | H27: =IFERROR(H25/H3,0) -> 0.61876493 | I27: =IFERROR(I25/I3,0) -> 0.64425933 | J27: =IFERROR(J25/J3,0) -> 0.66570172 | K27: =IFERROR(K25/K3,0) -> 0.60485 | AA27: =IFERROR(G27/G$3,0) -> 2.7644732e-05 | AB27: =IFERROR(H27/H$3,0) -> 2.1111052e-05 | AC27: =IFERROR(I27/I$3,0) -> 1.9730479e-05 | AD27: =IFERROR(J27/J$3,0) -> 1.8529803e-05 | AE27: =IFERROR(K27/K$3,0) -> 1.512125e-05 | AG27: =IFERROR(H27-G27,0) -> -0.047611344 | AH27: =IFERROR(I27-H27,0) -> 0.025494406 | AI27: =IFERROR(J27-I27,0) -> 0.021442387 | AJ27: =IFERROR(K27-J27,0) -> -0.06085172 | AL27: =IFERROR((H27-G27)/G27,0) -> -0.071448138 | AM27: =IFERROR((I27-H27)/H27,0) -> 0.041202087 | AN27: =IFERROR((J27-I27)/I27,0) -> 0.03328223 | AO27: =IFERROR((K27-J27)/J27,0) -> -0.091409889
A28: Impuesto sobre la renta | G28: 3752 | H28: 3179 | I28: 3764 | J28: 4173 | K28: 4136 | AA28: =IFERROR(G28/G$3,0) -> 0.15565235 | AB28: =IFERROR(H28/H$3,0) -> 0.10846128 | AC28: =IFERROR(I28/I$3,0) -> 0.11527272 | AD28: =IFERROR(J28/J$3,0) -> 0.11615543 | AE28: =IFERROR(K28/K$3,0) -> 0.1034 | AG28: =IFERROR(H28-G28,0) -> -573 | AH28: =IFERROR(I28-H28,0) -> 585 | AI28: =IFERROR(J28-I28,0) -> 409 | AJ28: =IFERROR(K28-J28,0) -> -37 | AL28: =IFERROR((H28-G28)/G28,0) -> -0.15271855 | AM28: =IFERROR((I28-H28)/H28,0) -> 0.18402013 | AN28: =IFERROR((J28-I28)/I28,0) -> 0.108661 | AO28: =IFERROR((K28-J28)/J28,0) -> -0.0088665229
A29: Beneficios netos para la empresa | G29: =IFERROR(G25-G28,0) -> 12311 | H29: =IFERROR(H25-H28,0) -> 14957 | I29: =IFERROR(I25-I28,0) -> 17273 | J29: =IFERROR(J25-J28,0) -> 19743 | K29: =IFERROR(K25-K28,0) -> 20058 | AA29: =IFERROR(G29/G$3,0) -> 0.51072392 | AB29: =IFERROR(H29/H$3,0) -> 0.51030365 | AC29: =IFERROR(I29/I$3,0) -> 0.52898662 | AD29: =IFERROR(J29/J$3,0) -> 0.54954629 | AE29: =IFERROR(K29/K$3,0) -> 0.50145 | AG29: =IFERROR(H29-G29,0) -> 2646 | AH29: =IFERROR(I29-H29,0) -> 2316 | AI29: =IFERROR(J29-I29,0) -> 2470 | AJ29: =IFERROR(K29-J29,0) -> 315 | AL29: =IFERROR((H29-G29)/G29,0) -> 0.21492974 | AM29: =IFERROR((I29-H29)/H29,0) -> 0.15484389 | AN29: =IFERROR((J29-I29)/I29,0) -> 0.14299774 | AO29: =IFERROR((K29-J29)/J29,0) -> 0.015955022
A30: Intereses minoritarios | G30: - | H30: - | I30: - | J30: - | K30: - | AA30: =IFERROR(G30/G$3,0) -> 0 | AB30: =IFERROR(H30/H$3,0) -> 0 | AC30: =IFERROR(I30/I$3,0) -> 0 | AD30: =IFERROR(J30/J$3,0) -> 0 | AE30: =IFERROR(K30/K$3,0) -> 0 | AG30: =IFERROR(H30-G30,0) -> 0 | AH30: =IFERROR(I30-H30,0) -> 0 | AI30: =IFERROR(J30-I30,0) -> 0 | AJ30: =IFERROR(K30-J30,0) -> 0 | AL30: =IFERROR((H30-G30)/G30,0) -> 0 | AM30: =IFERROR((I30-H30)/H30,0) -> 0 | AN30: =IFERROR((J30-I30)/I30,0) -> 0 | AO30: =IFERROR((K30-J30)/J30,0) -> 0
A31: Beneficio neto | G31: =IFERROR(G29-SUM(G30),0) -> 12311 | H31: =IFERROR(H29-SUM(H30),0) -> 14957 | I31: =IFERROR(I29-SUM(I30),0) -> 17273 | J31: =IFERROR(J29-SUM(J30),0) -> 19743 | K31: =IFERROR(K29-SUM(K30),0) -> 20058 | AA31: =IFERROR(G31/G$3,0) -> 0.51072392 | AB31: =IFERROR(H31/H$3,0) -> 0.51030365 | AC31: =IFERROR(I31/I$3,0) -> 0.52898662 | AD31: =IFERROR(J31/J$3,0) -> 0.54954629 | AE31: =IFERROR(K31/K$3,0) -> 0.50145 | AG31: =IFERROR(H31-G31,0) -> 2646 | AH31: =IFERROR(I31-H31,0) -> 2316 | AI31: =IFERROR(J31-I31,0) -> 2470 | AJ31: =IFERROR(K31-J31,0) -> 315 | AL31: =IFERROR((H31-G31)/G31,0) -> 0.21492974 | AM31: =IFERROR((I31-H31)/H31,0) -> 0.15484389 | AN31: =IFERROR((J31-I31)/I31,0) -> 0.14299774 | AO31: =IFERROR((K31-J31)/J31,0) -> 0.015955022
A32: Crecimiento del beneficio neto | G32: 0.133 | H32: =IFERROR((H31-G31)/G31,0) -> 0.21492974 | I32: =IFERROR((I31-H31)/H31,0) -> 0.15484389 | J32: =IFERROR((J31-I31)/I31,0) -> 0.14299774 | K32: =IFERROR((K31-J31)/J31,0) -> 0.015955022 | AA32: =IFERROR(G32/G$3,0) -> 5.5175275e-06 | AB32: =IFERROR(H32/H$3,0) -> 7.3329832e-06 | AC32: =IFERROR(I32/I$3,0) -> 4.7421029e-06 | AD32: =IFERROR(J32/J$3,0) -> 3.9803413e-06 | AE32: =IFERROR(K32/K$3,0) -> 3.9887555e-07 | AG32: =IFERROR(H32-G32,0) -> 0.081929738 | AH32: =IFERROR(I32-H32,0) -> -0.060085852 | AI32: =IFERROR(J32-I32,0) -> -0.011846144 | AJ32: =IFERROR(K32-J32,0) -> -0.12704272 | AL32: =IFERROR((H32-G32)/G32,0) -> 0.61601306 | AM32: =IFERROR((I32-H32)/H32,0) -> -0.27956044 | AN32: =IFERROR((J32-I32)/I32,0) -> -0.076503787 | AO32: =IFERROR((K32-J32)/J32,0) -> -0.88842466
A33: Margen del beneficio neto % | G33: =IFERROR(G31/G3,0) -> 0.51072392 | H33: =IFERROR(H31/H3,0) -> 0.51030365 | I33: =IFERROR(I31/I3,0) -> 0.52898662 | J33: =IFERROR(J31/J3,0) -> 0.54954629 | K33: =IFERROR(K31/K3,0) -> 0.50145 | AA33: =IFERROR(G33/G$3,0) -> 2.1187468e-05 | AB33: =IFERROR(H33/H$3,0) -> 1.7410565e-05 | AC33: =IFERROR(I33/I$3,0) -> 1.6200246e-05 | AD33: =IFERROR(J33/J$3,0) -> 1.5296618e-05 | AE33: =IFERROR(K33/K$3,0) -> 1.253625e-05 | AG33: =IFERROR(H33-G33,0) -> -0.00042026557 | AH33: =IFERROR(I33-H33,0) -> 0.018682966 | AI33: =IFERROR(J33-I33,0) -> 0.020559673 | AJ33: =IFERROR(K33-J33,0) -> -0.04809629 | AL33: =IFERROR((H33-G33)/G33,0) -> -0.0008228821 | AM33: =IFERROR((I33-H33)/H33,0) -> 0.036611469 | AN33: =IFERROR((J33-I33)/I33,0) -> 0.038866149 | AO33: =IFERROR((K33-J33)/J33,0) -> -0.087519997
A34: Dividendo preferente y otros ajustes | G34: 303 | H34: 327 | I34: 284 | J34: 286 | K34: 205 | AA34: =IFERROR(G34/G$3,0) -> 0.012570006 | AB34: =IFERROR(H34/H$3,0) -> 0.011156602 | AC34: =IFERROR(I34/I$3,0) -> 0.0086975163 | AD34: =IFERROR(J34/J$3,0) -> 0.0079608083 | AE34: =IFERROR(K34/K$3,0) -> 0.005125 | AG34: =IFERROR(H34-G34,0) -> 24 | AH34: =IFERROR(I34-H34,0) -> -43 | AI34: =IFERROR(J34-I34,0) -> 2 | AJ34: =IFERROR(K34-J34,0) -> -81 | AL34: =IFERROR((H34-G34)/G34,0) -> 0.079207921 | AM34: =IFERROR((I34-H34)/H34,0) -> -0.13149847 | AN34: =IFERROR((J34-I34)/I34,0) -> 0.0070422535 | AO34: =IFERROR((K34-J34)/J34,0) -> -0.28321678
A35: Beneficio neto sobre ingresos ordinarios | G35: =IFERROR(G31-G34,0) -> 12008 | H35: =IFERROR(H31-H34,0) -> 14630 | I35: =IFERROR(I31-I34,0) -> 16989 | J35: =IFERROR(J31-J34,0) -> 19457 | K35: =IFERROR(K31-K34,0) -> 19853 | AA35: =IFERROR(G35/G$3,0) -> 0.49815391 | AB35: =IFERROR(H35/H$3,0) -> 0.49914705 | AC35: =IFERROR(I35/I$3,0) -> 0.5202891 | AD35: =IFERROR(J35/J$3,0) -> 0.54158548 | AE35: =IFERROR(K35/K$3,0) -> 0.496325 | AG35: =IFERROR(H35-G35,0) -> 2622 | AH35: =IFERROR(I35-H35,0) -> 2359 | AI35: =IFERROR(J35-I35,0) -> 2468 | AJ35: =IFERROR(K35-J35,0) -> 396 | AL35: =IFERROR((H35-G35)/G35,0) -> 0.21835443 | AM35: =IFERROR((I35-H35)/H35,0) -> 0.16124402 | AN35: =IFERROR((J35-I35)/I35,0) -> 0.14527047 | AO35: =IFERROR((K35-J35)/J35,0) -> 0.020352572
A36: BPA básico: Crecimiento de actividades continuadas | G36: 5.66 | H36: 7.56 | I36: 8.33 | J36: 9.78 | K36: 10.23 | AA36: =IFERROR(G36/G$3,0) -> 0.00023480606 | AB36: =IFERROR(H36/H$3,0) -> 0.00025793245 | AC36: =IFERROR(I36/I$3,0) -> 0.00025510673 | AD36: =IFERROR(J36/J$3,0) -> 0.00027222624 | AE36: =IFERROR(K36/K$3,0) -> 0.00025575 | AG36: =IFERROR(H36-G36,0) -> 1.9 | AH36: =IFERROR(I36-H36,0) -> 0.77 | AI36: =IFERROR(J36-I36,0) -> 1.45 | AJ36: =IFERROR(K36-J36,0) -> 0.45 | AL36: =IFERROR((H36-G36)/G36,0) -> 0.33568905 | AM36: =IFERROR((I36-H36)/H36,0) -> 0.10185185 | AN36: =IFERROR((J36-I36)/I36,0) -> 0.17406963 | AO36: =IFERROR((K36-J36)/J36,0) -> 0.04601227
A37: BPA básico: crecimiento de actividades continuadas | G37: 0.1538 | H37: =IFERROR((H36-G36)/G36,0) -> 0.33568905 | I37: =IFERROR((I36-H36)/H36,0) -> 0.10185185 | J37: =IFERROR((J36-I36)/I36,0) -> 0.17406963 | K37: =IFERROR((K36-J36)/J36,0) -> 0.04601227 | AA37: =IFERROR(G37/G$3,0) -> 6.380419e-06 | AB37: =IFERROR(H37/H$3,0) -> 1.1453055e-05 | AC37: =IFERROR(I37/I$3,0) -> 3.1192188e-06 | AD37: =IFERROR(J37/J$3,0) -> 4.8452271e-06 | AE37: =IFERROR(K37/K$3,0) -> 1.1503067e-06 | AG37: =IFERROR(H37-G37,0) -> 0.18188905 | AH37: =IFERROR(I37-H37,0) -> -0.23383719 | AI37: =IFERROR(J37-I37,0) -> 0.072217776 | AJ37: =IFERROR(K37-J37,0) -> -0.12805736 | AL37: =IFERROR((H37-G37)/G37,0) -> 1.1826336 | AM37: =IFERROR((I37-H37)/H37,0) -> -0.69658869 | AN37: =IFERROR((J37-I37)/I37,0) -> 0.70904726 | AO37: =IFERROR((K37-J37)/J37,0) -> -0.73566744
A38: BPA diluido: Crecimiento de actividades continuadas | G38: 5.63 | H38: 7 | I38: 8.28 | J38: 9.73 | K38: 10.2 | AA38: =IFERROR(G38/G$3,0) -> 0.0002335615 | AB38: =IFERROR(H38/H$3,0) -> 0.00023882634 | AC38: =IFERROR(I38/I$3,0) -> 0.00025357548 | AD38: =IFERROR(J38/J$3,0) -> 0.00027083449 | AE38: =IFERROR(K38/K$3,0) -> 0.000255 | AG38: =IFERROR(H38-G38,0) -> 1.37 | AH38: =IFERROR(I38-H38,0) -> 1.28 | AI38: =IFERROR(J38-I38,0) -> 1.45 | AJ38: =IFERROR(K38-J38,0) -> 0.47 | AL38: =IFERROR((H38-G38)/G38,0) -> 0.24333925 | AM38: =IFERROR((I38-H38)/H38,0) -> 0.18285714 | AN38: =IFERROR((J38-I38)/I38,0) -> 0.17512077 | AO38: =IFERROR((K38-J38)/J38,0) -> 0.048304214
A39: BPA diluido: Actividades continuadas | G39: 0.1511 | H39: =IFERROR((H38-G38)/G38,0) -> 0.24333925 | I39: =IFERROR((I38-H38)/H38,0) -> 0.18285714 | J39: =IFERROR((J38-I38)/I38,0) -> 0.17512077 | K39: =IFERROR((K38-J38)/J38,0) -> 0.048304214 | AA39: =IFERROR(G39/G$3,0) -> 6.268409e-06 | AB39: =IFERROR(H39/H$3,0) -> 8.3022605e-06 | AC39: =IFERROR(I39/I$3,0) -> 5.6000105e-06 | AD39: =IFERROR(J39/J$3,0) -> 4.8744857e-06 | AE39: =IFERROR(K39/K$3,0) -> 1.2076053e-06 | AG39: =IFERROR(H39-G39,0) -> 0.092239254 | AH39: =IFERROR(I39-H39,0) -> -0.060482111 | AI39: =IFERROR(J39-I39,0) -> -0.0077363699 | AJ39: =IFERROR(K39-J39,0) -> -0.12681656 | AL39: =IFERROR((H39-G39)/G39,0) -> 0.61045171 | AM39: =IFERROR((I39-H39)/H39,0) -> -0.24855057 | AN39: =IFERROR((J39-I39)/I39,0) -> -0.042308273 | AO39: =IFERROR((K39-J39)/J39,0) -> -0.72416628
A40: Promedio ponderado básico de acciones en circulación | G40: 2120.6 | H40: 1936 | I40: 2038.95 | J40: 1989.72 | K40: 1940.45 | AA40: =IFERROR(G40/G$3,0) -> 0.087973449 | AB40: =IFERROR(H40/H$3,0) -> 0.066052542 | AC40: =IFERROR(I40/I$3,0) -> 0.062442961 | AD40: =IFERROR(J40/J$3,0) -> 0.055383845 | AE40: =IFERROR(K40/K$3,0) -> 0.04851125 | AG40: =IFERROR(H40-G40,0) -> -184.6 | AH40: =IFERROR(I40-H40,0) -> 102.95 | AI40: =IFERROR(J40-I40,0) -> -49.23 | AJ40: =IFERROR(K40-J40,0) -> -49.27 | AL40: =IFERROR((H40-G40)/G40,0) -> -0.087050835 | AM40: =IFERROR((I40-H40)/H40,0) -> 0.053176653 | AN40: =IFERROR((J40-I40)/I40,0) -> -0.02414478 | AO40: =IFERROR((K40-J40)/J40,0) -> -0.024762278
...

Sheet Supuestos FCL
A1: SUPUESTOS PARA EL MODELO DE FLUJO DE CAJA LIBRE (FCL) - VISA INC.
A4: A. DATOS GENERALES
A5: Concepto | B5: Valor | C5: Fuente / Nota
A6: Cierre de año fiscal de VISA | B6: 30-sep | C6: 10-K de VISA Inc. (SEC EDGAR)
A7: Horizonte histórico analizado | B7: FY2021-FY2025 | C7: Taller - Análisis financiero VISA - LyL.xlsx (Balance, PyG)
A8: Horizonte de proyección del FCL | B8: FY2026-FY2030 (5 años) | C8: Supuesto propio, igual al horizonte usado en los ejercicios de clase
A10: B. DATOS BASE - AÑO FISCAL 2025
A11: Concepto | B11: Valor | C11: Fuente / Nota
A12: Ingresos totales 2024 (US$ MM) | B12: 35926 | C12: Taller VISA, hoja PyG - Ingresos totales
A13: Ingresos totales 2025 (US$ MM) | B13: 40000 | C13: Taller VISA, hoja PyG - Ingresos totales
A14: EBIT 2025 (US$ MM) | B14: 26808 | C14: Taller VISA, hoja PyG - EBIT
A15: Margen EBIT 2025 | B15: =$B$14/$B$13 -> 0.6702 | C15: Calculado = EBIT 2025 / Ingresos 2025
A16: D&A 2025 (US$ MM) | B16: 1220 | C16: Taller VISA, hoja PyG (EBITDA - EBIT = 28,028 - 26,808)
A17: % D&A / Ingresos 2025 | B17: =$B$16/$B$13 -> 0.0305 | C17: Calculado = D&A 2025 / Ingresos 2025
A18: Capex real 2025 (US$ MM) | B18: 1482 | C18: stockanalysis.com, Estado de flujo de efectivo de VISA (basado en 10-K); no se usa el neto de PP&E del Balance porque no discrimina retiros de activos
A19: % Capex / Ingresos 2025 | B19: =$B$18/$B$13 -> 0.03705 | C19: Calculado = Capex 2025 / Ingresos 2025
A20: Cuentas por cobrar 2025 (US$ MM) | B20: 7317 | C20: Taller VISA, hoja Balance
A21: Proveedores 2025 (US$ MM) | B21: 555 | C21: Taller VISA, hoja Balance
A22: KTNO 2025 (US$ MM) = CxC + Inventario(0) - Proveedores | B22: =$B$20-$B$21 -> 6762
A23: % KTNO / Ingresos 2025 | B23: =$B$22/$B$13 -> 0.16905 | C23: Calculado = KTNO 2025 / Ingresos 2025
A24: Tasa de impuesto de renta efectiva 2025 | B24: 0.170951 | C24: Taller VISA, hoja EVA (Empresa) = Impuesto de renta / EBT 2025
A25: Deuda financiera total 2025 (US$ MM) | B25: 26084 | C25: Taller VISA, hoja Balance / WACC Visa
A26: Efectivo y equivalentes 2025 (US$ MM) | B26: 17164 | C26: Taller VISA, hoja Balance
A27: Deuda neta 2025 (US$ MM) | B27: =$B$25-$B$26 -> 8920
A28: Acciones en circulación 2025 (millones) | B28: 1966 | C28: Taller VISA, hoja Ratios (Acciones en circulación)
A29: Precio de mercado 2025 (US$/acción) | B29: 223.6465 | C29: Taller VISA, hoja Ratios (Precio de mercado)
A31: C. SUPUESTOS DE PROYECCIÓN FY2026-FY2030
A32: Concepto | B32: Valor | C32: Fuente / Nota
A33: Crecimiento de ingresos FY2026 | B33: 0.11 | C33: Consenso de analistas: ingresos FY2026 proyectados en ~US$45,000-45,800 MM (Yahoo Finance / Stockanalysis.com forecast, sep-2026)
A34: Crecimiento de ingresos FY2027 | B34: 0.105 | C34: Consenso de analistas: ingresos FY2027 proyectados en ~US$49,700-50,600 MM (Yahoo Finance / Stockanalysis.com forecast, sep-2026)
A35: Crecimiento de ingresos FY2028 | B35: 0.095 | C35: Supuesto propio: desaceleración gradual hacia el crecimiento de largo plazo de una empresa madura de gran capitalización
A36: Crecimiento de ingresos FY2029 | B36: 0.09 | C36: Supuesto propio: continúa la convergencia gradual del crecimiento
A37: Crecimiento de ingresos FY2030 | B37: 0.085 | C37: Supuesto propio: continúa la convergencia gradual del crecimiento
A38: Margen EBIT proyectado (constante FY26-FY30) | B38: =$B$15 -> 0.6702 | C38: Supuesto propio: se mantiene el margen operativo 2025 dado el modelo de negocio de red de pagos, altamente escalable y con costos incrementales bajos
A39: % D&A / Ingresos proyectado (constante) | B39: =$B$17 -> 0.0305 | C39: Supuesto propio: la depreciación y amortización se mantiene proporcional a los ingresos
A40: % Capex / Ingresos proyectado (constante) | B40: =$B$19 -> 0.03705 | C40: Supuesto propio: la inversión en activos fijos se mantiene proporcional al crecimiento del negocio
A41: % KTNO / Ingresos proyectado (constante) | B41: =$B$23 -> 0.16905 | C41: Supuesto propio: la necesidad de capital de trabajo neto operativo se mantiene proporcional a los ingresos
A42: Tasa de impuesto de renta proyectada (constante) | B42: =$B$24 -> 0.170951 | C42: Supuesto propio: se mantiene la tasa efectiva de 2025
A43: WACC (método Empresa - beta de regresión) usado para descontar el FCL | B43: 0.064487 | C43: Taller VISA, hoja 'WACC Visa' (panel 'Empresa')
A44: WACC (método Sector - beta apalancada Damodaran), alterno para sensibilidad | B44: 0.074677 | C44: Taller VISA, hoja 'WACC Visa' (panel 'Sector')
...

Sheet FCL Histórico
A1: SUPUESTOS PARA EL MODELO DE FLUJO DE CAJA LIBRE (FCL) - VISA INC.
A3: B. DATOS BASE - AÑO FISCAL 2025
A4: Ingresos totales 2024 (US$ MM) | B4: 35926
A5: Ingresos totales 2025 (US$ MM) | B5: 40000
A6: EBIT 2025 (US$ MM) | B6: 26808
A7: Margen EBIT 2025 | B7: =+B6/B5 -> 0.6702
A8: D&A 2025 (US$ MM) | B8: 1220
A9: % D&A / Ingresos 2025 | B9: =+B8/B5 -> 0.0305
A10: Capex real 2025 (US$ MM) | B10: 1482
A11: % Capex / Ingresos 2025 | B11: =+B10/B5 -> 0.03705
A12: Cuentas por cobrar 2025 (US$ MM) | B12: 7317
A13: Proveedores 2025 (US$ MM) | B13: 555
A14: KTNO 2025 (US$ MM) = CxC + Inventario(0) - Proveedores | B14: =+B12-B13 -> 6762
A15: % KTNO / Ingresos 2025 | B15: =+B14/B5 -> 0.16905
A16: Tasa de impuesto de renta efectiva 2025 | B16: 0.170951
A17: Deuda financiera total 2025 (US$ MM) | B17: 26084
A18: Efectivo y equivalentes 2025 (US$ MM) | B18: 17164
A19: Deuda neta 2025 (US$ MM) | B19: =+B17-B18 -> 8920
A20: Acciones en circulación 2025 (millones) | B20: 1966
A21: Precio de mercado 2025 (US$/acción) | B21: 223.6465
A23: FLUJO DE CAJA LIBRE HISTÓRICO - VISA INC. (FY2021-FY2025)
A25: CIFRAS DE ESTADOS FINANCIEROS
A26: Concepto | B26: 2021 | C26: 2022 | D26: 2023 | E26: 2024 | F26: 2025
A27: Ingresos totales | B27: 24105 | C27: 29310 | D27: 32653 | E27: 35926 | F27: 40000
A28: EBIT (Utilidad Operacional) | B28: 15807 | C28: 19681 | D28: 21927 | E28: 23996 | F28: 26808
A29: EBITDA | B29: 16611 | C29: 20542 | D29: 22870 | E29: 25030 | F29: 28028
A30: Tasa de impuesto de renta efectiva | B30: 0.23358 | C30: 0.175287 | D30: 0.178923 | E30: 0.174486 | F30: 0.170951
A31: Capex real (fuente stockanalysis.com, CFI) | B31: 705 | C31: 970 | D31: 1059 | E31: 1257 | F31: 1482
A32: Cuentas por cobrar | B32: 3726 | C32: 3952 | D32: 4474 | E32: 7015 | F32: 7317
A33: Inventario | B33: 0 | C33: 0 | D33: 0 | E33: 0 | F33: 0
A34: Proveedores | B34: 266 | C34: 340 | D34: 375 | E34: 479 | F34: 555
A36: CÁLCULO DEL KTNO
A37: Concepto | B37: 2021 | C37: 2022 | D37: 2023 | E37: 2024 | F37: 2025
A38: Cuentas por cobrar | B38: =+B32 -> 3726 | C38: =+C32 -> 3952 | D38: =+D32 -> 4474 | E38: =+E32 -> 7015 | F38: =+F32 -> 7317
A39: (+) Inventario | B39: =+B33 -> 0 | C39: =+C33 -> 0 | D39: =+D33 -> 0 | E39: =+E33 -> 0 | F39: =+F33 -> 0
A40: (-) Proveedores | B40: =-B34 -> -266 | C40: =-C34 -> -340 | D40: =-D34 -> -375 | E40: =-E34 -> -479 | F40: =-F34 -> -555
